{"time":"2023-04-30 17:56:49","level":"CRITICAL","module":"exceptions","method":"handle_exception","line":85,"path":"C:\\ProgramData\\anaconda3\\lib\\site-packages\\anaconda_navigator\\exceptions.py","message":"sequence item 0: expected str instance, NoneType found","exception":"Traceback (most recent call last):\n  File \"C:\\ProgramData\\anaconda3\\lib\\site-packages\\anaconda_navigator\\exceptions.py\", line 74, in exception_handler\n    return_value = func(*args, **kwargs)\n  File \"C:\\ProgramData\\anaconda3\\lib\\site-packages\\anaconda_navigator\\app\\start.py\", line 137, in start_app\n    window = run_app(splash)\n  File \"C:\\ProgramData\\anaconda3\\lib\\site-packages\\anaconda_navigator\\app\\start.py\", line 59, in run_app\n    window = MainWindow(splash=splash)\n  File \"C:\\ProgramData\\anaconda3\\lib\\site-packages\\anaconda_navigator\\widgets\\main_window\\__init__.py\", line 219, in __init__\n    self.api = AnacondaAPI()\n  File \"C:\\ProgramData\\anaconda3\\lib\\site-packages\\anaconda_navigator\\api\\anaconda_api.py\", line 1085, in AnacondaAPI\n    ANACONDA_API = _AnacondaAPI()\n  File \"C:\\ProgramData\\anaconda3\\lib\\site-packages\\anaconda_navigator\\api\\anaconda_api.py\", line 69, in __init__\n    self._conda_api = CondaAPI()\n  File \"C:\\ProgramData\\anaconda3\\lib\\site-packages\\anaconda_navigator\\api\\conda_api\\__init__.py\", line 1735, in CondaAPI\n    CONDA_API = _CondaAPI()\n  File \"C:\\ProgramData\\anaconda3\\lib\\site-packages\\anaconda_navigator\\api\\conda_api\\__init__.py\", line 429, in __init__\n    self.set_conda_prefix(info=get_conda_info(allow_fixes=True))\n  File \"C:\\ProgramData\\anaconda3\\lib\\site-packages\\anaconda_navigator\\api\\conda_api\\__init__.py\", line 576, in set_conda_prefix\n    info = worker.communicate()[0]\n  File \"C:\\ProgramData\\anaconda3\\lib\\site-packages\\anaconda_navigator\\api\\conda_api\\__init__.py\", line 276, in communicate\n    logger.debug('[CONDA] %s', ' '.join(self._cmd_list), extra={\nTypeError: sequence item 0: expected str instance, NoneType found"}
{"time":"2023-05-01 17:07:45","level":"INFO","module":"__init__","method":"__init__","line":264,"path":"C:\\ProgramData\\anaconda3\\lib\\site-packages\\anaconda_navigator\\widgets\\main_window\\__init__.py","message":"appusermodelid: 0"}
{"time":"2023-05-01 17:07:52","level":"INFO","module":"__init__","method":"setup","line":473,"path":"C:\\ProgramData\\anaconda3\\lib\\site-packages\\anaconda_navigator\\widgets\\main_window\\__init__.py","message":"Initial setup"}
{"time":"2023-05-01 17:14:59","level":"ERROR","module":"__init__","method":"_conda_output_ready","line":1062,"path":"C:\\ProgramData\\anaconda3\\lib\\site-packages\\anaconda_navigator\\widgets\\main_window\\__init__.py","message":"Multiple Errors Encountered."}
{"time":"2023-05-01 17:15:28","level":"INFO","module":"__init__","method":"setup","line":489,"path":"C:\\ProgramData\\anaconda3\\lib\\site-packages\\anaconda_navigator\\widgets\\main_window\\__init__.py","message":"Normal setup"}
{"time":"2023-05-01 17:25:27","level":"ERROR","module":"__init__","method":"_conda_output_ready","line":1062,"path":"C:\\ProgramData\\anaconda3\\lib\\site-packages\\anaconda_navigator\\widgets\\main_window\\__init__.py","message":"Multiple Errors Encountered."}
{"time":"2023-05-01 17:25:52","level":"INFO","module":"__init__","method":"setup","line":489,"path":"C:\\ProgramData\\anaconda3\\lib\\site-packages\\anaconda_navigator\\widgets\\main_window\\__init__.py","message":"Normal setup"}
